Workbook

Sheet NC testable
A1: TP_BMC_GPIOA0 | B1: U25W4.80, | C1: 30.00,30.00 | D1: 50mil
A2: TP_ME_RCVR_BOOT | B2: J7G3.1, | C2: 64.00,64.00 | D2: 100 mil
A3: TP_BIOS_USB_RECOVERY | B3: J7G3.2, | C3: 64.00,64.00 | D3: 100 mil
A4: TP_PASSWORD_CLEAR | B4: J7G3.7, | C4: 64.00,64.00 | D4: 100 mil
A5: TP_BIOS_RECOVER_BOOT | B5: J7G3.8, | C5: 64.00,64.00 | D5: 100 mil
A6: TP_JUMPER_BLOCK_1_1 | B6: J8G2.1, | C6: 19*19mil via | D6: 100 mil
A7: TP_JUMPER_BLOCK_1_2 | B7: J8G2.2, | C7: 19*19mil via | D7: 100 mil
A8: TP_JUMPER_BLOCK_1_7 | B8: J8G2.7, | C8: 19*19mil via | D8: 100 mil
A9: TP_JUMPER_BLOCK_1_8 | B9: J8G2.8, | C9: 19*19mil via | D9: 100 mil
A10: TP_RST_RTCRST_N | B10: J9G1.2, | C10: 19*19mil via | D10: 100 mil
A11: TP_IE_DEBUG_MODE | B11: J9G1.7, | C11: 19*19mil via | D11: 100 mil
A12: TP_FAN_1 | B12: J1B2.6, | C12: 19*19mil via | D12: 100 mil
... A858: TP_CPU1_RSVD_85 | B858: U2D1.1622, | C858: 19.00,19.00 | D858: 100 mil

Sheet NC untestable
A1: TP_SPI_0_1 | B1: U7F1.13, | C1: 因VIA未開防焊並且可植針位置被元件覆蓋
A2: NC_6256 | B2: J2W1.22, | C2: 因VIA未開防焊並且可植針位置被元件覆蓋
A3: NC_6257 | B3: J2W1.23, | C3: 因VIA未開防焊並且可植針位置被元件覆蓋
A4: NC_6258 | B4: J2W2.22, | C4: 因VIA未開防焊並且可植針位置被元件覆蓋
A5: NC_6259 | B5: J2W2.23, | C5: 因VIA未開防焊並且可植針位置被元件覆蓋
A6: TP_CPLD1_PB16A_PCLKT2_1 | B6: U8D7.249, | C6: 因VIA未開防焊
A7: TP_CPLD1_PB25B_SI_SISPI | B7: U8D7.221, | C7: 因VIA未開防焊
A8: TP_CPLD1_PB5A_CSSPIN | B8: U8D7.229, | C8: 因VIA未開防焊
A9: TP_CPLD1_PB8A_MCLK_CCLK | B9: U8D7.214, | C9: 因VIA未開防焊
A10: TP_CPLD1_PR10C | B10: U8D7.139, | C10: 因VIA未開防焊
A11: TP_CPLD1_PR11B | B11: U8D7.174, | C11: 因VIA未開防焊
A12: TP_CPLD1_PR12D | B12: U8D7.173, | C12: 因VIA未開防焊
... A159: TP_CPU0_RSVD_69 | B159: U5D1.1822, | C159: 因可植針位置被元件覆蓋

Sheet Definition
B1: Definition :
B2: 2.Net information:
B3: No. | C3: Item | D3: Definition : | E3: Example
B4: 1 | C4: Connecting two or more component pins | D4: There is a NET connecting two or more component pins （Test point/Via are not componet）
B5: 2 | C5: Only single component pin is connecting No Connected (NC) | D5: Net只連到一個元件交 （測點/Via不算元件）
B6: 3 | C6: Independent component pins No Connected (NC) | D6: 元件腳沒有引出線路，包括DIP和SMD腳
B7: 4 | C7: Not connected to any component | D7: NET不與任何元件相連，如孤立的孔，PAD等
B9: 3. Nets Coverage : 以下皆為連接2個以上元件腳的NET
B10: No. | C10: Item | D10: Definition :
B11: 1 | C11: 因不符合DFT要求而無法植針的net 數 | D11: 板子有layout 測點，但不符合DFT要求，導致無法植針的net數
B12: 2 | C12: Q'ty of high speed nets | D12: 板子上高速信號的總net數
B13: 3 | C13: Q'ty of high speed nets with test piont | D13: 板子上有測點高速信號的net數
B14: 4 | C14: Testable nets Coverage (including high speed nets) | D14: 公式：含高速信號net的Coverage =（測試點數總數-不符合DFT的測點數）/總net數
B15: 5 | C15: Testable nets Coverage (excluding high speed nets) | D15: 公式：不含高速信號net的Coverage =（測試點數總數-不符合DFT的測點數-有測點的高速信號net數）/（總net數-高速信號的總net數）
B17: 6. Power and GND nodes quantity, sufficient test points are required to supply power:
B18: No. | C18: Net Name | D18: Need Q'ty | E18: Actual Q'ty
B19: 1 | C19: GND | D19: 可測TP總數/32
B20: 2 | C20: Every Power Signal | D20: 每個探針能承受的最大電流

Sheet Net coverage summary
B1: ICT Test Point (Nets) Testability Analysis Report
AA2: Analyzer:
C3: 1. Model information: | AA3: Date:
C4: 1 | D4: Model Name
C5: 2 | D5: PCB Version
C6: 3 | D6: PCB Size
C8: 2. Net information: | AD8: Nets | AF8: Testable | AH8: Untestable
C9: 1 | D9: Connecting two or more component pins | AD9: =AF9+AH9 -> 0 | AF9: =COUNTA('Testable nets list'!B:B)-1-AF10-AF11 -> 0 | AH9: =COUNTA('Untestable nets list'!C:C)-1-AH10-AH11 -> 0
C10: 2 | D10: Only single component pin is connecting | AD10: =COUNTA('Nets not required'!B:B)-1 -> 0 | AF10: =COUNTIFS('Testable nets list'!H:H,"Y") -> 0 | AH10: =COUNTIFS('Untestable nets list'!E:E,"Y") -> 0
C11: 3 | D11: Independent component pins | AD11: =COUNTA('Nets not required'!E:E)-1 -> 0 | AF11: =COUNTIFS('Testable nets list'!I:I,"Y") -> 0 | AH11: =COUNTIFS('Untestable nets list'!F:F,"Y") -> 0
C12: 4 | D12: Not connected to any component | AD12: =COUNTA('Nets not required'!K:K)-1 -> 0 | AF12: - | AH12: =AD12 -> 0
C13: Total | AD13: =AF13+AH13 -> 0 | AF13: =SUM(AF9:AF12) -> 0 | AH13: =SUM(AH9:AH12) -> 0
C15: 3. Nets Coverage: The following are all Connecting two or more component pins
C16: 1 | D16: Total nets number | AD16: =AD9 -> 0
C17: 2 | D17: Untestable nets number (不可選點的nets總數) | AD17: =AH9 -> 0
C18: 3 | D18: There are test nets, but not conform the DFT request, so can't build test probe(from: Don't need DFT net list sheet)
C19: 4 | D19: Q'ty of high speed nets(RD) | AD19: 0
C20: 5 | D20: Q'ty of high speed nets with test piont | AD20: 0
C21: 6 | D21: Testable nets Coverage (including high speed nets) | AD21: =(AD16-AD17-AD18)/AD16 -> #DIV/0!
C22: 7 | D22: Testable nets Coverage (excluding high speed nets) | AD22: =IF(COUNTA('Nets not required'!H:H)>1,(AD16-AD17-AD18-AD20)/(AD16-AD19)," ")
C24: 4. Test point type, quantity, and allocation
C25: Type Size | F25: Top Side | R25: Bottom Side | AD25: Summary | AG25: Percentage
F26: Test Pad | I26: VIA | L26: DIP | O26: Bead/MECA | R26: Test Pad | U26: VIA | X26: DIP | AA26: Bead/MECA
C27: 100mil | F27: =COUNTIFS('Testable nets list'!G:G,5,'Testable nets list'!F:F,1,'Testable nets list'!D:D,"T") -> 0 | I27: =COUNTIFS('Testable nets list'!G:G,6,'Testable nets list'!F:F,1,'Testable nets list'!D:D,"T") -> 0 | L27: =COUNTIFS('Testable nets list'!G:G,7,'Testable nets list'!F:F,1,'Testable nets list'!D:D,"T") -> 0 | O27: - | R27: =COUNTIFS('Testable nets list'!G:G,5,'Testable nets list'!F:F,1,'Testable nets list'!D:D,"B") -> 0 | U27: =COUNTIFS('Testable nets list'!G:G,6,'Testable nets list'!F:F,1,'Testable nets list'!D:D,"B") -> 0 | X27: =COUNTIFS('Testable nets list'!G:G,7,'Testable nets list'!F:F,1,'Testable nets list'!D:D,"B") -> 0 | AA27: - | AD27: =SUM(F27:AC27) -> 0 | AG27: =AD27/AD31 -> #DIV/0!
C28: 75mil | F28: =COUNTIFS('Testable nets list'!G:G,5,'Testable nets list'!F:F,2,'Testable nets list'!D:D,"T") -> 0 | I28: =COUNTIFS('Testable nets list'!G:G,6,'Testable nets list'!F:F,2,'Testable nets list'!D:D,"T") -> 0 | L28: =COUNTIFS('Testable nets list'!G:G,7,'Testable nets list'!F:F,2,'Testable nets list'!D:D,"T") -> 0 | O28: - | R28: =COUNTIFS('Testable nets list'!G:G,5,'Testable nets list'!F:F,2,'Testable nets list'!D:D,"B") -> 0 | U28: =COUNTIFS('Testable nets list'!G:G,6,'Testable nets list'!F:F,2,'Testable nets list'!D:D,"B") -> 0 | X28: =COUNTIFS('Testable nets list'!G:G,7,'Testable nets list'!F:F,2,'Testable nets list'!D:D,"B") -> 0 | AA28: - | AD28: =SUM(F28:AC28) -> 0 | AG28: =AD28/AD31 -> #DIV/0!
C29: 50mil | F29: =COUNTIFS('Testable nets list'!G:G,5,'Testable nets list'!F:F,3,'Testable nets list'!D:D,"T") -> 0 | I29: =COUNTIFS('Testable nets list'!G:G,6,'Testable nets list'!F:F,3,'Testable nets list'!D:D,"T") -> 0 | L29: =COUNTIFS('Testable nets list'!G:G,7,'Testable nets list'!F:F,3,'Testable nets list'!D:D,"T") -> 0 | O29: - | R29: =COUNTIFS('Testable nets list'!G:G,5,'Testable nets list'!F:F,3,'Testable nets list'!D:D,"B") -> 0 | U29: =COUNTIFS('Testable nets list'!G:G,6,'Testable nets list'!F:F,3,'Testable nets list'!D:D,"B") -> 0 | X29: =COUNTIFS('Testable nets list'!G:G,7,'Testable nets list'!F:F,3,'Testable nets list'!D:D,"B") -> 0 | AA29: - | AD29: =SUM(F29:AC29) -> 0 | AG29: =AD29/AD31 -> #DIV/0!
C30: 39mil | D30: 39mil | F30: =COUNTIFS('Testable nets list'!G:G,5,'Testable nets list'!F:F,4,'Testable nets list'!D:D,"T") -> 0 | I30: =COUNTIFS('Testable nets list'!G:G,6,'Testable nets list'!F:F,4,'Testable nets list'!D:D,"T") -> 0 | L30: =COUNTIFS('Testable nets list'!G:G,7,'Testable nets list'!F:F,4,'Testable nets list'!D:D,"T") -> 0 | O30: - | R30: =COUNTIFS('Testable nets list'!G:G,5,'Testable nets list'!F:F,4,'Testable nets list'!D:D,"B") -> 0 | U30: =COUNTIFS('Testable nets list'!G:G,6,'Testable nets list'!F:F,4,'Testable nets list'!D:D,"B") -> 0 | X30: =COUNTIFS('Testable nets list'!G:G,7,'Testable nets list'!F:F,4,'Testable nets list'!D:D,"B") -> 0 | AA30: - | AD30: =SUM(F30:AC30) -> 0 | AG30: =AD30/AD31 -> #DIV/0!
C31: Total | D31: Totoal | F31: =SUM(F27:H30) -> 0 | I31: =SUM(I27:K30) -> 0 | L31: =SUM(L27:N30) -> 0 | O31: =SUM(O27:Q30) -> 0 | R31: =SUM(R27:T30) -> 0 | U31: =SUM(U27:W30) -> 0 | X31: =SUM(X27:Z30) -> 0 | AA31: =SUM(AA27:AC30) -> 0 | AD31: =SUM(F31:AC31) -> 0 | AG31: =1 -> 1
C32: * Percentage of nets with 75mil and 100mil Test Point (TP) Spacing(>=85%) : | AG32: =(AD27+AD28)/AD31 -> #DIV/0!
C33: * Percentage of nets with "Test Pad" or "VIA" test points(>=85%): | AG33: =(F31+I31+R31+U31)/AD31 -> #DIV/0!
C34: * Percentage of nets with test points on bottom side(>=85%): | AG34: =(R31+U31+X31+AA31)/AD31 -> #DIV/0!
C36: 5. Test point size, quantity, and allocation
C37: No. | D37: Testpoint Size | J37: Pad | N37: Via | R37: DIP | V37: Subtotal | Z37: Percentage
C38: 1 | D38: 24mil x 24mil | J38: T | K38: =COUNTIFS('Testable nets list'!D:D,"T",'Testable nets list'!E:E,"24.00,24.00",'Testable nets list'!G:G,"5") -> 0 | N38: T | O38: =COUNTIFS('Testable nets list'!D:D,"T",'Testable nets list'!E:E,"24.00,24.00",'Testable nets list'!G:G,"6") -> 0 | R38: T | S38: =COUNTIFS('Testable nets list'!D:D,"T",'Testable nets list'!E:E,"24.00,24.00",'Testable nets list'!G:G,"7") -> 0 | V38: =K38+O38+S38 -> 0 | Z38: =V38/($AD$13-$AF$13) -> #DIV/0!
J39: B | K39: =COUNTIFS('Testable nets list'!D:D,"B",'Testable nets list'!E:E,"24.00,24.00",'Testable nets list'!G:G,"5") -> 0 | N39: B | O39: =COUNTIFS('Testable nets list'!D:D,"B",'Testable nets list'!E:E,"24.00,24.00",'Testable nets list'!G:G,"6") -> 0 | R39: B | S39: =COUNTIFS('Testable nets list'!D:D,"B",'Testable nets list'!E:E,"24.00,24.00",'Testable nets list'!G:G,"7") -> 0 | V39: =K39+O39+S39 -> 0 | Z39: =V39/($AD$13-$AF$13) -> #DIV/0!
C40: 2 | D40: 小於24mil (不含Bead/MECA) | J40: T | K40: =COUNTIFS('Testable nets list'!D:D,"T",'Testable nets list'!E:E,"22.00,22.00",'Testable nets list'!G:G,"5")+COUNTIFS('Testable nets list'!D:D,"T",'Testable nets list'!E:E,"20.00,20.00",'Testable nets list'!G:G,"5")+COUNTIFS('Testable nets list'!D:D,"T",'Testable nets list'!E:E,"18.00,18.00",'Testable nets list'!G:G,"5") -> 0 | N40: T | O40: =COUNTIFS('Testable nets list'!D:D,"T",'Testable nets list'!E:E,"22.00,22.00",'Testable nets list'!G:G,"6")+COUNTIFS('Testable nets list'!D:D,"T",'Testable nets list'!E:E,"20.00,20.00",'Testable nets list'!G:G,"6")+COUNTIFS('Testable nets list'!D:D,"T",'Testable nets list'!E:E,"18.00,18.00",'Testable nets list'!G:G,"6") -> 0 | R40: T | S40: =COUNTIFS('Testable nets list'!D:D,"T",'Testable nets list'!E:E,"22.00,22.00",'Testable nets list'!G:G,"7")+COUNTIFS('Testable nets list'!D:D,"T",'Testable nets list'!E:E,"20.00,20.00",'Testable nets list'!G:G,"7")+COUNTIFS('Testable nets list'!D:D,"T",'Testable nets list'!E:E,"18.00,18.00",'Testable nets list'!G:G,"7") -> 0 | V40: =K40+O40+S40 -> 0 | Z40: =V40/($AD$13-$AF$13) -> #DIV/0!
J41: B | K41: =COUNTIFS('Testable nets list'!D:D,"B",'Testable nets list'!E:E,"22.00,22.00",'Testable nets list'!G:G,"5")+COUNTIFS('Testable nets list'!D:D,"B",'Testable nets list'!E:E,"20.00,20.00",'Testable nets list'!G:G,"5")+COUNTIFS('Testable nets list'!D:D,"B",'Testable nets list'!E:E,"18.00,18.00",'Testable nets list'!G:G,"5") -> 0 | N41: B | O41: =COUNTIFS('Testable nets list'!D:D,"B",'Testable nets list'!E:E,"22.00,22.00",'Testable nets list'!G:G,"6")+COUNTIFS('Testable nets list'!D:D,"B",'Testable nets list'!E:E,"20.00,20.00",'Testable nets list'!G:G,"6")+COUNTIFS('Testable nets list'!D:D,"B",'Testable nets list'!E:E,"18.00,18.00",'Testable nets list'!G:G,"6") -> 0 | R41: B | S41: =COUNTIFS('Testable nets list'!D:D,"B",'Testable nets list'!E:E,"22.00,22.00",'Testable nets list'!G:G,"7")+COUNTIFS('Testable nets list'!D:D,"B",'Testable nets list'!E:E,"20.00,20.00",'Testable nets list'!G:G,"7")+COUNTIFS('Testable nets list'!D:D,"B",'Testable nets list'!E:E,"18.00,18.00",'Testable nets list'!G:G,"7") -> 0 | V41: =K41+O41+S41 -> 0 | Z41: =V41/($AD$13-$AF$13) -> #DIV/0!
C43: 6. Power and GND nodes quantity, sufficient test points are required to supply power:
C44: No. | D44: Net Name | P44: Need Q'ty | S44: Actual Q'ty
C45: 1
...

Sheet Testable nets list
A1: No. | B1: Net Name | C1: Connected Component List | D1: Top/Bottom | E1: PAD size | F1: Probe type | G1: Point type | H1: single component pin connecting | I1: Independent component pins | J1: HSS | K1: Remark
A2: 1 | H2: =VLOOKUP(B:B,'Nets not required'!B:C,2,0) -> #N/A | I2: =VLOOKUP(B:B,'Nets not required'!E:F,2,0) -> #N/A | J2: =VLOOKUP(B:B,'Nets not required'!H:I,2,0) -> #N/A | K2: =MID(B2,1,4)
A3: 2 | H3: =VLOOKUP(B:B,'Nets not required'!B:C,2,0) -> #N/A | I3: =VLOOKUP(B:B,'Nets not required'!E:F,2,0) -> #N/A | J3: =VLOOKUP(B:B,'Nets not required'!H:I,2,0) -> #N/A | K3: =MID(B3,1,4)
A4: 3 | H4: =VLOOKUP(B:B,'Nets not required'!B:C,2,0) -> #N/A | I4: =VLOOKUP(B:B,'Nets not required'!E:F,2,0) -> #N/A | J4: =VLOOKUP(B:B,'Nets not required'!H:I,2,0) -> #N/A | K4: =MID(B4,1,4)
A5: 4 | H5: =VLOOKUP(B:B,'Nets not required'!B:C,2,0) -> #N/A | I5: =VLOOKUP(B:B,'Nets not required'!E:F,2,0) -> #N/A | J5: =VLOOKUP(B:B,'Nets not required'!H:I,2,0) -> #N/A | K5: =MID(B5,1,4)
A6: 5 | H6: =VLOOKUP(B:B,'Nets not required'!B:C,2,0) -> #N/A | I6: =VLOOKUP(B:B,'Nets not required'!E:F,2,0) -> #N/A | J6: =VLOOKUP(B:B,'Nets not required'!H:I,2,0) -> #N/A | K6: =MID(B6,1,4)
A7: 6 | H7: =VLOOKUP(B:B,'Nets not required'!B:C,2,0) -> #N/A | I7: =VLOOKUP(B:B,'Nets not required'!E:F,2,0) -> #N/A | J7: =VLOOKUP(B:B,'Nets not required'!H:I,2,0) -> #N/A | K7: =MID(B7,1,4)
A8: 7 | H8: =VLOOKUP(B:B,'Nets not required'!B:C,2,0) -> #N/A | I8: =VLOOKUP(B:B,'Nets not required'!E:F,2,0) -> #N/A | J8: =VLOOKUP(B:B,'Nets not required'!H:I,2,0) -> #N/A | K8: =MID(B8,1,4)
A9: 8 | H9: =VLOOKUP(B:B,'Nets not required'!B:C,2,0) -> #N/A | I9: =VLOOKUP(B:B,'Nets not required'!E:F,2,0) -> #N/A | J9: =VLOOKUP(B:B,'Nets not required'!H:I,2,0) -> #N/A | K9: =MID(B9,1,4)
A10: 9 | H10: =VLOOKUP(B:B,'Nets not required'!B:C,2,0) -> #N/A | I10: =VLOOKUP(B:B,'Nets not required'!E:F,2,0) -> #N/A | J10: =VLOOKUP(B:B,'Nets not required'!H:I,2,0) -> #N/A | K10: =MID(B10,1,4)
A11: 10 | H11: =VLOOKUP(B:B,'Nets not required'!B:C,2,0) -> #N/A | I11: =VLOOKUP(B:B,'Nets not required'!E:F,2,0) -> #N/A | J11: =VLOOKUP(B:B,'Nets not required'!H:I,2,0) -> #N/A | K11: =MID(B11,1,4)
A12: 11 | H12: =VLOOKUP(B:B,'Nets not required'!B:C,2,0) -> #N/A | I12: =VLOOKUP(B:B,'Nets not required'!E:F,2,0) -> #N/A | J12: =VLOOKUP(B:B,'Nets not required'!H:I,2,0) -> #N/A | K12: =MID(B12,1,4)
A13: 12 | H13: =VLOOKUP(B:B,'Nets not required'!B:C,2,0) -> #N/A | I13: =VLOOKUP(B:B,'Nets not required'!E:F,2,0) -> #N/A | J13: =VLOOKUP(B:B,'Nets not required'!H:I,2,0) -> #N/A | K13: =MID(B13,1,4)
... A25: 26 | H25: =VLOOKUP(B:B,'Nets not required'!B:C,2,0) -> #N/A | I25: =VLOOKUP(B:B,'Nets not required'!E:F,2,0) -> #N/A | J25: =VLOOKUP(B:B,'Nets not required'!H:I,2,0) -> #N/A | K25: =MID(B25,1,4)

Sheet Nets not required
A1: No. | B1: Only single component pin connecting | D1: No. | E1: Independent component pins | G1: No. | H1: High speed sginals | J1: No. | K1: Not connected to any component
A2: 1 | D2: 1 | G2: 1 | J2: 1
A3: 2 | D3: 2 | G3: 2 | J3: 2
J4: 3
J5: 4
J6: 5
J7: 6

Sheet Untestable nets list
B1: No. | C1: Net Name | D1: Connected Component List | E1: Only single component pin connecting | F1: Independent component pins | G1: HSS | H1: Remark
B2: 1 | E2: =VLOOKUP(C:C,'Nets not required'!B:C,2,0) -> #N/A | F2: =VLOOKUP(C:C,'Nets not required'!E:F,2,0) -> #N/A | G2: =VLOOKUP(C:C,'Nets not required'!H:I,2,0) -> #N/A
B3: 2 | E3: =VLOOKUP(C:C,'Nets not required'!B:C,2,0) -> #N/A | F3: =VLOOKUP(C:C,'Nets not required'!E:F,2,0) -> #N/A | G3: =VLOOKUP(C:C,'Nets not required'!H:I,2,0) -> #N/A

Sheet Don't need DFT net list
B1: Not conform the DFT request Net Name, so can't build test probe
B2: No. | C2: Net Name | D2: Connected Component List | E2: Only single component pin connecting | F2: Independent component pins | G2: HSS | H2: Remark | I2: Probe type
B3: 1 | E3: =VLOOKUP($C$3:$C$93,'Nets not required'!$B$2:$C$3,2,0) -> #N/A | F3: =VLOOKUP($C$3:$C$93,'Nets not required'!$E$2:$F$3,2,0) -> #N/A | G3: =VLOOKUP($C$3:$C$93,'Nets not required'!#REF!,2,0) -> #REF!
B4: 2 | E4: =VLOOKUP($C$3:$C$93,'Nets not required'!$B$2:$C$3,2,0) -> #N/A | F4: =VLOOKUP($C$3:$C$93,'Nets not required'!$E$2:$F$3,2,0) -> #N/A | G4: =VLOOKUP($C$3:$C$93,'Nets not required'!#REF!,2,0) -> #REF!
B5: 3 | E5: =VLOOKUP($C$3:$C$93,'Nets not required'!$B$2:$C$3,2,0) -> #N/A | F5: =VLOOKUP($C$3:$C$93,'Nets not required'!$E$2:$F$3,2,0) -> #N/A | G5: =VLOOKUP($C$3:$C$93,'Nets not required'!#REF!,2,0) -> #REF!
B6: 4 | E6: =VLOOKUP($C$3:$C$93,'Nets not required'!$B$2:$C$3,2,0) -> #N/A | F6: =VLOOKUP($C$3:$C$93,'Nets not required'!$E$2:$F$3,2,0) -> #N/A | G6: =VLOOKUP($C$3:$C$93,'Nets not required'!#REF!,2,0) -> #REF!
B7: 5 | E7: =VLOOKUP($C$3:$C$93,'Nets not required'!$B$2:$C$3,2,0) -> #N/A | F7: =VLOOKUP($C$3:$C$93,'Nets not required'!$E$2:$F$3,2,0) -> #N/A | G7: =VLOOKUP($C$3:$C$93,'Nets not required'!#REF!,2,0) -> #REF!
B8: 6 | E8: =VLOOKUP($C$3:$C$93,'Nets not required'!$B$2:$C$3,2,0) -> #N/A | F8: =VLOOKUP($C$3:$C$93,'Nets not required'!$E$2:$F$3,2,0) -> #N/A | G8: =VLOOKUP($C$3:$C$93,'Nets not required'!#REF!,2,0) -> #REF!
B9: 7 | E9: =VLOOKUP($C$3:$C$93,'Nets not required'!$B$2:$C$3,2,0) -> #N/A | F9: =VLOOKUP($C$3:$C$93,'Nets not required'!$E$2:$F$3,2,0) -> #N/A | G9: =VLOOKUP($C$3:$C$93,'Nets not required'!#REF!,2,0) -> #REF!
B10: 8 | E10: =VLOOKUP($C$3:$C$93,'Nets not required'!$B$2:$C$3,2,0) -> #N/A | F10: =VLOOKUP($C$3:$C$93,'Nets not required'!$E$2:$F$3,2,0) -> #N/A | G10: =VLOOKUP($C$3:$C$93,'Nets not required'!#REF!,2,0) -> #REF!
B11: 9 | E11: =VLOOKUP($C$3:$C$93,'Nets not required'!$B$2:$C$3,2,0) -> #N/A | F11: =VLOOKUP($C$3:$C$93,'Nets not required'!$E$2:$F$3,2,0) -> #N/A | G11: =VLOOKUP($C$3:$C$93,'Nets not required'!#REF!,2,0) -> #REF!
B12: 10 | E12: =VLOOKUP($C$3:$C$93,'Nets not required'!$B$2:$C$3,2,0) -> #N/A | F12: =VLOOKUP($C$3:$C$93,'Nets not required'!$E$2:$F$3,2,0) -> #N/A | G12: =VLOOKUP($C$3:$C$93,'Nets not required'!#REF!,2,0) -> #REF!
B13: 11 | E13: =VLOOKUP($C$3:$C$93,'Nets not required'!$B$2:$C$3,2,0) -> #N/A | F13: =VLOOKUP($C$3:$C$93,'Nets not required'!$E$2:$F$3,2,0) -> #N/A | G13: =VLOOKUP($C$3:$C$93,'Nets not required'!#REF!,2,0) -> #REF!
B14: 12 | E14: =VLOOKUP($C$3:$C$93,'Nets not required'!$B$2:$C$3,2,0) -> #N/A | F14: =VLOOKUP($C$3:$C$93,'Nets not required'!$E$2:$F$3,2,0) -> #N/A | G14: =VLOOKUP($C$3:$C$93,'Nets not required'!#REF!,2,0) -> #REF!
... B19: 17 | E19: =VLOOKUP($C$3:$C$93,'Nets not required'!$B$2:$C$3,2,0) -> #N/A | F19: =VLOOKUP($C$3:$C$93,'Nets not required'!$E$2:$F$3,2,0) -> #N/A | G19: =VLOOKUP($C$3:$C$93,'Nets not required'!#REF!,2,0) -> #REF!

Sheet 工作表1
A1: 1 | B1: 与高度大于10mm元件间距<120mil
A2: 2 | B2: 与高度为5~10mm元件间距<120mil
A3: 3 | B3: 与高度为2.5~5mm元件间距<38mil
A4: 4 | B4: 与高度小于2.5mm元件间距<25mil
A5: 5 | B5: 与BGA间距<45mil
